Workbook

Sheet List
C1: My text here | D1: Max character = | E1: 45
A2: KC_NO | B2: 0x0000 | D2: X ( | E2: =LEFT(A2 & REPT(" ",$E$1),$E$1) -> KC_NO | F2: , | G2: =B2 -> 0x0000 | H2: , " | I2: =IF(C2="","",C2) | J2: " ) \ | K2: =IF(I2="","",_xlfn.CONCAT(D2:J2))
A3: KC_TRANSPARENT | B3: 0x0001 | D3: X ( | E3: =LEFT(A3 & REPT(" ",$E$1),$E$1) -> KC_TRANSPARENT | F3: , | G3: =B3 -> 0x0001 | H3: , " | I3: =IF(C3="","",C3) | J3: " ) \ | K3: =IF(I3="","",_xlfn.CONCAT(D3:J3))
A4: KC_A | B4: 0x0004 | C4: a | D4: X ( | E4: =LEFT(A4 & REPT(" ",$E$1),$E$1) -> KC_A | F4: , | G4: =B4 -> 0x0004 | H4: , " | I4: =IF(C4="","",C4) -> a | J4: " ) \ | K4: =IF(I4="","",_xlfn.CONCAT(D4:J4)) -> X ( KC_A , 0x0004, "a" ) \
A5: KC_B | B5: 0x0005 | C5: b | D5: X ( | E5: =LEFT(A5 & REPT(" ",$E$1),$E$1) -> KC_B | F5: , | G5: =B5 -> 0x0005 | H5: , " | I5: =IF(C5="","",C5) -> b | J5: " ) \ | K5: =IF(I5="","",_xlfn.CONCAT(D5:J5)) -> X ( KC_B , 0x0005, "b" ) \
A6: KC_C | B6: 0x0006 | C6: c | D6: X ( | E6: =LEFT(A6 & REPT(" ",$E$1),$E$1) -> KC_C | F6: , | G6: =B6 -> 0x0006 | H6: , " | I6: =IF(C6="","",C6) -> c | J6: " ) \ | K6: =IF(I6="","",_xlfn.CONCAT(D6:J6)) -> X ( KC_C , 0x0006, "c" ) \
A7: KC_D | B7: 0x0007 | C7: d | D7: X ( | E7: =LEFT(A7 & REPT(" ",$E$1),$E$1) -> KC_D | F7: , | G7: =B7 -> 0x0007 | H7: , " | I7: =IF(C7="","",C7) -> d | J7: " ) \ | K7: =IF(I7="","",_xlfn.CONCAT(D7:J7)) -> X ( KC_D , 0x0007, "d" ) \
A8: KC_E | B8: 0x0008 | C8: e | D8: X ( | E8: =LEFT(A8 & REPT(" ",$E$1),$E$1) -> KC_E | F8: , | G8: =B8 -> 0x0008 | H8: , " | I8: =IF(C8="","",C8) -> e | J8: " ) \ | K8: =IF(I8="","",_xlfn.CONCAT(D8:J8)) -> X ( KC_E , 0x0008, "e" ) \
A9: KC_F | B9: 0x0009 | C9: f | D9: X ( | E9: =LEFT(A9 & REPT(" ",$E$1),$E$1) -> KC_F | F9: , | G9: =B9 -> 0x0009 | H9: , " | I9: =IF(C9="","",C9) -> f | J9: " ) \ | K9: =IF(I9="","",_xlfn.CONCAT(D9:J9)) -> X ( KC_F , 0x0009, "f" ) \
A10: KC_G | B10: 0x000A | C10: g | D10: X ( | E10: =LEFT(A10 & REPT(" ",$E$1),$E$1) -> KC_G | F10: , | G10: =B10 -> 0x000A | H10: , " | I10: =IF(C10="","",C10) -> g | J10: " ) \ | K10: =IF(I10="","",_xlfn.CONCAT(D10:J10)) -> X ( KC_G , 0x000A, "g" ) \
A11: KC_H | B11: 0x000B | C11: h | D11: X ( | E11: =LEFT(A11 & REPT(" ",$E$1),$E$1) -> KC_H | F11: , | G11: =B11 -> 0x000B | H11: , " | I11: =IF(C11="","",C11) -> h | J11: " ) \ | K11: =IF(I11="","",_xlfn.CONCAT(D11:J11)) -> X ( KC_H , 0x000B, "h" ) \
A12: KC_I | B12: 0x000C | C12: i | D12: X ( | E12: =LEFT(A12 & REPT(" ",$E$1),$E$1) -> KC_I | F12: , | G12: =B12 -> 0x000C | H12: , " | I12: =IF(C12="","",C12) -> i | J12: " ) \ | K12: =IF(I12="","",_xlfn.CONCAT(D12:J12)) -> X ( KC_I , 0x000C, "i" ) \
A13: KC_J | B13: 0x000D | C13: j | D13: X ( | E13: =LEFT(A13 & REPT(" ",$E$1),$E$1) -> KC_J | F13: , | G13: =B13 -> 0x000D | H13: , " | I13: =IF(C13="","",C13) -> j | J13: " ) \ | K13: =IF(I13="","",_xlfn.CONCAT(D13:J13)) -> X ( KC_J , 0x000D, "j" ) \
A14: KC_K | B14: 0x000E | C14: k | D14: X ( | E14: =LEFT(A14 & REPT(" ",$E$1),$E$1) -> KC_K | F14: , | G14: =B14 -> 0x000E | H14: , " | I14: =IF(C14="","",C14) -> k | J14: " ) \ | K14: =IF(I14="","",_xlfn.CONCAT(D14:J14)) -> X ( KC_K , 0x000E, "k" ) \
A15: KC_L | B15: 0x000F | C15: l | D15: X ( | E15: =LEFT(A15 & REPT(" ",$E$1),$E$1) -> KC_L | F15: , | G15: =B15 -> 0x000F | H15: , " | I15: =IF(C15="","",C15) -> l | J15: " ) \ | K15: =IF(I15="","",_xlfn.CONCAT(D15:J15)) -> X ( KC_L , 0x000F, "l" ) \
... A29: KC_Z | B29: 0x001D | C29: z | D29: X ( | E29: =LEFT(A29 & REPT(" ",$E$1),$E$1) -> KC_Z | F29: , | G29: =B29 -> 0x001D | H29: , " | I29: =IF(C29="","",C29) -> z | J29: " ) \ | K29: =IF(I29="","",_xlfn.CONCAT(D29:J29)) -> X ( KC_Z , 0x001D, "z" ) \
A30: KC_1 | B30: 0x001E | C30: 1 | D30: X ( | E30: =LEFT(A30 & REPT(" ",$E$1),$E$1) -> KC_1 | F30: , | G30: =B30 -> 0x001E | H30: , " | I30: =IF(C30="","",C30) -> 1 | J30: " ) \ | K30: =IF(I30="","",_xlfn.CONCAT(D30:J30)) -> X ( KC_1 , 0x001E, "1" ) \
A31: KC_2 | B31: 0x001F | C31: 2 | D31: X ( | E31: =LEFT(A31 & REPT(" ",$E$1),$E$1) -> KC_2 | F31: , | G31: =B31 -> 0x001F | H31: , " | I31: =IF(C31="","",C31) -> 2 | J31: " ) \ | K31: =IF(I31="","",_xlfn.CONCAT(D31:J31)) -> X ( KC_2 , 0x001F, "2" ) \
A32: KC_3 | B32: 0x0020 | C32: 3 | D32: X ( | E32: =LEFT(A32 & REPT(" ",$E$1),$E$1) -> KC_3 | F32: , | G32: =B32 -> 0x0020 | H32: , " | I32: =IF(C32="","",C32) -> 3 | J32: " ) \ | K32: =IF(I32="","",_xlfn.CONCAT(D32:J32)) -> X ( KC_3 , 0x0020, "3" ) \
A33: KC_4 | B33: 0x0021 | C33: 4 | D33: X ( | E33: =LEFT(A33 & REPT(" ",$E$1),$E$1) -> KC_4 | F33: , | G33: =B33 -> 0x0021 | H33: , " | I33: =IF(C33="","",C33) -> 4 | J33: " ) \ | K33: =IF(I33="","",_xlfn.CONCAT(D33:J33)) -> X ( KC_4 , 0x0021, "4" ) \
A34: KC_5 | B34: 0x0022 | C34: 5 | D34: X ( | E34: =LEFT(A34 & REPT(" ",$E$1),$E$1) -> KC_5 | F34: , | G34: =B34 -> 0x0022 | H34: , " | I34: =IF(C34="","",C34) -> 5 | J34: " ) \ | K34: =IF(I34="","",_xlfn.CONCAT(D34:J34)) -> X ( KC_5 , 0x0022, "5" ) \
A35: KC_6 | B35: 0x0023 | C35: 6 | D35: X ( | E35: =LEFT(A35 & REPT(" ",$E$1),$E$1) -> KC_6 | F35: , | G35: =B35 -> 0x0023 | H35: , " | I35: =IF(C35="","",C35) -> 6 | J35: " ) \ | K35: =IF(I35="","",_xlfn.CONCAT(D35:J35)) -> X ( KC_6 , 0x0023, "6" ) \
A36: KC_7 | B36: 0x0024 | C36: 7 | D36: X ( | E36: =LEFT(A36 & REPT(" ",$E$1),$E$1) -> KC_7 | F36: , | G36: =B36 -> 0x0024 | H36: , " | I36: =IF(C36="","",C36) -> 7 | J36: " ) \ | K36: =IF(I36="","",_xlfn.CONCAT(D36:J36)) -> X ( KC_7 , 0x0024, "7" ) \
A37: KC_8 | B37: 0x0025 | C37: 8 | D37: X ( | E37: =LEFT(A37 & REPT(" ",$E$1),$E$1) -> KC_8 | F37: , | G37: =B37 -> 0x0025 | H37: , " | I37: =IF(C37="","",C37) -> 8 | J37: " ) \ | K37: =IF(I37="","",_xlfn.CONCAT(D37:J37)) -> X ( KC_8 , 0x0025, "8" ) \
A38: KC_9 | B38: 0x0026 | C38: 9 | D38: X ( | E38: =LEFT(A38 & REPT(" ",$E$1),$E$1) -> KC_9 | F38: , | G38: =B38 -> 0x0026 | H38: , " | I38: =IF(C38="","",C38) -> 9 | J38: " ) \ | K38: =IF(I38="","",_xlfn.CONCAT(D38:J38)) -> X ( KC_9 , 0x0026, "9" ) \
A39: KC_0 | B39: 0x0027 | C39: 0 | D39: X ( | E39: =LEFT(A39 & REPT(" ",$E$1),$E$1) -> KC_0 | F39: , | G39: =B39 -> 0x0027 | H39: , " | I39: =IF(C39="","",C39) -> 0 | J39: " ) \ | K39: =IF(I39="","",_xlfn.CONCAT(D39:J39)) -> X ( KC_0 , 0x0027, "0" ) \
A40: KC_ENTER | B40: 0x0028 | C40: Ent | D40: X ( | E40: =LEFT(A40 & REPT(" ",$E$1),$E$1) -> KC_ENTER | F40: , | G40: =B40 -> 0x0028 | H40: , " | I40: =IF(C40="","",C40) -> Ent | J40: " ) \ | K40: =IF(I40="","",_xlfn.CONCAT(D40:J40)) -> X ( KC_ENTER , 0x0028, "Ent" ) \
A41: KC_ESCAPE | B41: 0x0029 | C41: Esc | D41: X ( | E41: =LEFT(A41 & REPT(" ",$E$1),$E$1) -> KC_ESCAPE | F41: , | G41: =B41 -> 0x0029 | H41: , " | I41: =IF(C41="","",C41) -> Esc | J41: " ) \ | K41: =IF(I41="","",_xlfn.CONCAT(D41:J41)) -> X ( KC_ESCAPE , 0x0029, "Esc" ) \
A42: KC_BACKSPACE | B42: 0x002A | C42: BKSP | D42: X ( | E42: =LEFT(A42 & REPT(" ",$E$1),$E$1) -> KC_BACKSPACE | F42: , | G42: =B42 -> 0x002A | H42: , " | I42: =IF(C42="","",C42) -> BKSP | J42: " ) \ | K42: =IF(I42="","",_xlfn.CONCAT(D42:J42)) -> X ( KC_BACKSPACE , 0x002A, "BKSP" ) \
A43: KC_TAB | B43: 0x002B | C43: Tab | D43: X ( | E43: =LEFT(A43 & REPT(" ",$E$1),$E$1) -> KC_TAB | F43: , | G43: =B43 -> 0x002B | H43: , " | I43: =IF(C43="","",C43) -> Tab | J43: " ) \ | K43: =IF(I43="","",_xlfn.CONCAT(D43:J43)) -> X ( KC_TAB , 0x002B, "Tab" ) \
A44: KC_SPACE | B44: 0x002C | C44: _ | D44: X ( | E44: =LEFT(A44 & REPT(" ",$E$1),$E$1) -> KC_SPACE | F44: , | G44: =B44 -> 0x002C | H44: , " | I44: =IF(C44="","",C44) -> _ | J44: " ) \ | K44: =IF(I44="","",_xlfn.CONCAT(D44:J44)) -> X ( KC_SPACE , 0x002C, "_" ) \
A45: KC_MINUS | B45: 0x002D | C45: - | D45: X ( | E45: =LEFT(A45 & REPT(" ",$E$1),$E$1) -> KC_MINUS | F45: , | G45: =B45 -> 0x002D | H45: , " | I45: =IF(C45="","",C45) -> - | J45: " ) \ | K45: =IF(I45="","",_xlfn.CONCAT(D45:J45)) -> X ( KC_MINUS , 0x002D, "-" ) \
A46: KC_EQUAL | B46: 0x002E | C46: = | D46: X ( | E46: =LEFT(A46 & REPT(" ",$E$1),$E$1) -> KC_EQUAL | F46: , | G46: =B46 -> 0x002E | H46: , " | I46: =IF(C46="","",C46) -> = | J46: " ) \ | K46: =IF(I46="","",_xlfn.CONCAT(D46:J46)) -> X ( KC_EQUAL , 0x002E, "=" ) \
A47: KC_LEFT_BRACKET | B47: 0x002F | D47: X ( | E47: =LEFT(A47 & REPT(" ",$E$1),$E$1) -> KC_LEFT_BRACKET | F47: , | G47: =B47 -> 0x002F | H47: , " | I47: =IF(C47="","",C47) | J47: " ) \ | K47: =IF(I47="","",_xlfn.CONCAT(D47:J47))
A48: KC_RIGHT_BRACKET | B48: 0x0030 | D48: X ( | E48: =LEFT(A48 & REPT(" ",$E$1),$E$1) -> KC_RIGHT_BRACKET | F48: , | G48: =B48 -> 0x0030 | H48: , " | I48: =IF(C48="","",C48) | J48: " ) \ | K48: =IF(I48="","",_xlfn.CONCAT(D48:J48))
A49: KC_BACKSLASH | B49: 0x0031 | D49: X ( | E49: =LEFT(A49 & REPT(" ",$E$1),$E$1) -> KC_BACKSLASH | F49: , | G49: =B49 -> 0x0031 | H49: , " | I49: =IF(C49="","",C49) | J49: " ) \ | K49: =IF(I49="","",_xlfn.CONCAT(D49:J49))
A50: KC_NONUS_HASH | B50: 0x0032 | D50: X ( | E50: =LEFT(A50 & REPT(" ",$E$1),$E$1) -> KC_NONUS_HASH | F50: , | G50: =B50 -> 0x0032 | H50: , " | I50: =IF(C50="","",C50) | J50: " ) \ | K50: =IF(I50="","",_xlfn.CONCAT(D50:J50))
A51: KC_SEMICOLON | B51: 0x0033 | D51: X ( | E51: =LEFT(A51 & REPT(" ",$E$1),$E$1) -> KC_SEMICOLON | F51: , | G51: =B51 -> 0x0033 | H51: , " | I51: =IF(C51="","",C51) | J51: " ) \ | K51: =IF(I51="","",_xlfn.CONCAT(D51:J51))
A52: KC_QUOTE | B52: 0x0034 | D52: X ( | E52: =LEFT(A52 & REPT(" ",$E$1),$E$1) -> KC_QUOTE | F52: , | G52: =B52 -> 0x0034 | H52: , " | I52: =IF(C52="","",C52) | J52: " ) \ | K52: =IF(I52="","",_xlfn.CONCAT(D52:J52))
A53: KC_GRAVE | B53: 0x0035 | D53: X ( | E53: =LEFT(A53 & REPT(" ",$E$1),$E$1) -> KC_GRAVE | F53: , | G53: =B53 -> 0x0035 | H53: , " | I53: =IF(C53="","",C53) | J53: " ) \ | K53: =IF(I53="","",_xlfn.CONCAT(D53:J53))
...

Sheet Filtered
A1: COPY THIS
A2: =IF(List!K2="","",List!K2)
A3: =IF(List!K3="","",List!K3)
A4: =IF(List!K4="","",List!K4) -> X ( KC_A , 0x0004, "a" ) \
A5: =IF(List!K5="","",List!K5) -> X ( KC_B , 0x0005, "b" ) \
A6: =IF(List!K6="","",List!K6) -> X ( KC_C , 0x0006, "c" ) \
A7: =IF(List!K7="","",List!K7) -> X ( KC_D , 0x0007, "d" ) \
A8: =IF(List!K8="","",List!K8) -> X ( KC_E , 0x0008, "e" ) \
A9: =IF(List!K9="","",List!K9) -> X ( KC_F , 0x0009, "f" ) \
A10: =IF(List!K10="","",List!K10) -> X ( KC_G , 0x000A, "g" ) \
A11: =IF(List!K11="","",List!K11) -> X ( KC_H , 0x000B, "h" ) \
A12: =IF(List!K12="","",List!K12) -> X ( KC_I , 0x000C, "i" ) \
A13: =IF(List!K13="","",List!K13) -> X ( KC_J , 0x000D, "j" ) \
... A1381: =IF(List!K1381="","",List!K1381)

Sheet Ranges
A1: Range Name | B1: Start | C1: End
A2: INTERNAL_KEYCODE_RANGE | B2: KC_NO | C2: KC_TRANSPARENT | D2: 0x0000 | E2: 0x0001
A3: BASIC_KEYCODE_RANGE | B3: KC_A | C3: KC_EXSEL | D3: 0x0004 | E3: 0x00A4
A4: SYSTEM_KEYCODE_RANGE | B4: KC_SYSTEM_POWER | C4: KC_SYSTEM_WAKE | D4: 0x00A5 | E4: 0x00A7
A5: CONSUMER_KEYCODE_RANGE | B5: KC_AUDIO_MUTE | C5: KC_LAUNCHPAD | D5: 0x00A8 | E5: 0x00C2
A6: MOUSE_KEYCODE_RANGE | B6: QK_MOUSE_CURSOR_UP | C6: QK_MOUSE_ACCELERATION_2 | D6: 0x00CD | E6: 0x00DF
A7: MODIFIER_KEYCODE_RANGE | B7: KC_LEFT_CTRL | C7: KC_RIGHT_GUI | D7: 0x00E0 | E7: 0x00E7
A8: SWAP_HANDS_KEYCODE_RANGE | B8: QK_SWAP_HANDS_TOGGLE | C8: QK_SWAP_HANDS_ONE_SHOT | D8: 0x56F0 | E8: 0x56F6
A9: MAGIC_KEYCODE_RANGE | B9: QK_MAGIC_SWAP_CONTROL_CAPS_LOCK | C9: QK_MAGIC_TOGGLE_ESCAPE_CAPS_LOCK | D9: 0x7000 | E9: 0x7022
A10: MIDI_KEYCODE_RANGE | B10: QK_MIDI_ON | C10: QK_MIDI_PITCH_BEND_UP | D10: 0x7100 | E10: 0x718F
A11: SEQUENCER_KEYCODE_RANGE | B11: QK_SEQUENCER_ON | C11: QK_SEQUENCER_STEPS_CLEAR | D11: 0x7200 | E11: 0x7208
A12: JOYSTICK_KEYCODE_RANGE | B12: QK_JOYSTICK_BUTTON_0 | C12: QK_JOYSTICK_BUTTON_31 | D12: 0x7400 | E12: 0x741F
A13: PROGRAMMABLE_BUTTON_KEYCODE_RANGE | B13: QK_PROGRAMMABLE_BUTTON_1 | C13: QK_PROGRAMMABLE_BUTTON_32
A14: AUDIO_KEYCODE_RANGE | B14: QK_AUDIO_ON | C14: QK_AUDIO_VOICE_PREVIOUS
A15: STENO_KEYCODE_RANGE | B15: QK_STENO_BOLT | C15: QK_STENO_COMB_MAX
A16: MACRO_KEYCODE_RANGE | B16: QK_MACRO_0 | C16: QK_MACRO_31 | D16: 0x7700 | E16: 0x771F
A17: CONNECTION_KEYCODE_RANGE | B17: QK_OUTPUT_AUTO | C17: QK_BLUETOOTH_PROFILE5
A18: BACKLIGHT_KEYCODE_RANGE | B18: QK_BACKLIGHT_ON | C18: QK_BACKLIGHT_TOGGLE_BREATHING
A19: LED_MATRIX_KEYCODE_RANGE | B19: QK_LED_MATRIX_ON | C19: QK_LED_MATRIX_FLAG_PREVIOUS
A20: UNDERGLOW_KEYCODE_RANGE | B20: QK_UNDERGLOW_TOGGLE | C20: QK_UNDERGLOW_SPEED_DOWN
A21: RGB_KEYCODE_RANGE | B21: RGB_MODE_PLAIN | C21: RGB_MODE_TWINKLE
A22: RGB_MATRIX_KEYCODE_RANGE | B22: QK_RGB_MATRIX_ON | C22: QK_RGB_MATRIX_FLAG_PREVIOUS
A23: QUANTUM_KEYCODE_RANGE | B23: QK_BOOTLOADER | C23: QK_LAYER_LOCK | D23: 0x7C00 | E23: 0x7C7B
A24: KB_KEYCODE_RANGE | B24: QK_KB_0 | C24: QK_KB_31
A25: USER_KEYCODE_RANGE | B25: QK_USER_0 | C25: QK_USER_31
